Workbook

Sheet AGR_JK_3304_KAB. BANJARNEGARA
A1: IDEM | B1: KODE | C1: WILAYAH | D1: LK | E1: PR | F1: JML
A2: 2 | B2: 33.04 | C2: KAB. BANJARNEGARA | D2: 539745 | E2: 521513 | F2: 1061258
A3: 3 | B3: 33.04.01 | C3: SUSUKAN | D3: 32943 | E3: 32364 | F3: 65307
A4: 4 | B4: 33.04.01.2001 | C4: BERTA | D4: 2055 | E4: 1961 | F4: 4016
A5: 4 | B5: 33.04.01.2002 | C5: DERIK | D5: 2140 | E5: 2124 | F5: 4264
A6: 4 | B6: 33.04.01.2003 | C6: GUMELEM WETAN | D6: 5459 | E6: 5274 | F6: 10733
A7: 4 | B7: 33.04.01.2004 | C7: GUMELEM KULON | D7: 5478 | E7: 5358 | F7: 10836
A8: 4 | B8: 33.04.01.2005 | C8: PENARUSAN WETAN | D8: 1489 | E8: 1455 | F8: 2944
A9: 4 | B9: 33.04.01.2006 | C9: PENARUSAN KULON | D9: 1330 | E9: 1344 | F9: 2674
A10: 4 | B10: 33.04.01.2007 | C10: BRENGKOK | D10: 1479 | E10: 1409 | F10: 2888
A11: 4 | B11: 33.04.01.2008 | C11: PEKIKIRAN | D11: 1459 | E11: 1398 | F11: 2857
A12: 4 | B12: 33.04.01.2009 | C12: PIASA WETAN | D12: 650 | E12: 672 | F12: 1322
A13: 4 | B13: 33.04.01.2010 | C13: KARANGSALAM | D13: 1400 | E13: 1471 | F13: 2871
... A300: 4 | B300: 33.04.20.2009 | C300: GENTANSARI | D300: 2963 | E300: 2832 | F300: 5795

Sheet Kab
A1: Agregat Penduduk per Kabupaten/Kota
A3: No | B3: Kabupaten/Kota | D3: Pria | F3: Wanita | H3: Jumlah
B4: Kode | C4: Nama | D4: Jumlah | E4: % | F4: Jumlah | G4: % | H4: Kab./Kota | I4: %
A5: 1 | B5: 33.04 | C5: BANJARNEGARA | D5: ='AGR_JK_3304_KAB. BANJARNEGARA'!D2 -> 539745 | E5: =D5/H5*100 -> 50.858981 | F5: ='AGR_JK_3304_KAB. BANJARNEGARA'!E2 -> 521513 | G5: =F5/H5*100 -> 49.141019 | H5: =D5+F5 -> 1061258 | I5: =H5/H5*100 -> 100
A6: Jumlah Total | D6: =D5 -> 539745 | E6: =E5 -> 50.858981 | F6: =F5 -> 521513 | G6: =G5 -> 49.141019 | H6: =H5 -> 1061258 | I6: =I5 -> 100

Sheet Kec
A1: Agregat Penduduk per Kecamatan
A3: Kabupaten/Kota : 33.04 BANJARNEGARA
A4: No | B4: Kecamatan | D4: Pria | F4: Wanita | H4: Jumlah
B5: Kode | C5: Nama | D5: Jumlah | E5: % | F5: Jumlah | G5: % | H5: Kecamatan | I5: %
A6: 1 | B6: {=_xlfn._xlws.FILTER('AGR_JK_3304_KAB. BANJARNEGARA'!B3:D300,LEN('AGR_JK_3304_KAB. BANJARNEGARA'!B3:B300)=8)} -> 33.04.01 | C6: SUSUKAN | D6: 32943 | E6: {=D6:D25/H$26*100} -> 3.1041462 | F6: {=_xlfn._xlws.FILTER('AGR_JK_3304_KAB. BANJARNEGARA'!E3:E300,LEN('AGR_JK_3304_KAB. BANJARNEGARA'!B3:B300)=8)} -> 32364 | G6: {=F6:F25/H$26*100} -> 3.0495883 | H6: {=_xlfn._xlws.FILTER('AGR_JK_3304_KAB. BANJARNEGARA'!F3:F300,LEN('AGR_JK_3304_KAB. BANJARNEGARA'!B3:B300)=8)} -> 65307 | I6: {=H6:H25/H$26*100} -> 6.1537345
A7: 2 | B7: 33.04.02 | C7: PURWOREJA KLAMPOK | D7: 24641 | E7: 2.3218671 | F7: 24419 | G7: 2.3009485 | H7: 49060 | I7: 4.6228156
A8: 3 | B8: 33.04.03 | C8: MANDIRAJA | D8: 41730 | E8: 3.9321258 | F8: 40835 | G8: 3.847792 | H8: 82565 | I8: 7.7799178
A9: 4 | B9: 33.04.04 | C9: PURWANEGARA | D9: 43297 | E9: 4.0797808 | F9: 42632 | G9: 4.0171193 | H9: 85929 | I9: 8.0969001
A10: 5 | B10: 33.04.05 | C10: BAWANG | D10: 33344 | E10: 3.1419316 | F10: 32685 | G10: 3.0798354 | H10: 66029 | I10: 6.221767
A11: 6 | B11: 33.04.06 | C11: BANJARNEGARA | D11: 35673 | E11: 3.3613881 | F11: 35373 | G11: 3.3331198 | H11: 71046 | I11: 6.6945078
A12: 7 | B12: 33.04.07 | C12: SIGALUH | D12: 16560 | E12: 1.5604123 | F12: 16262 | G12: 1.5323324 | H12: 32822 | I12: 3.0927446
A13: 8 | B13: 33.04.08 | C13: MADUKARA | D13: 23940 | E13: 2.2558134 | F13: 23071 | G13: 2.1739294 | H13: 47011 | I13: 4.4297428
A14: 9 | B14: 33.04.09 | C14: BANJARMANGU | D14: 24303 | E14: 2.2900181 | F14: 23176 | G14: 2.1838233 | H14: 47479 | I14: 4.4738414
A15: 10 | B15: 33.04.10 | C15: WANADADI | D15: 17867 | E15: 1.683568 | F15: 17509 | G15: 1.6498344 | H15: 35376 | I15: 3.3334024 | N15: `
A16: 11 | B16: 33.04.11 | C16: RAKIT | D16: 28498 | E16: 2.6853037 | F16: 27910 | G16: 2.6298977 | H16: 56408 | I16: 5.3152014
A17: 12 | B17: 33.04.12 | C17: PUNGGELAN | D17: 47023 | E17: 4.4308735 | F17: 44789 | G17: 4.2203687 | H17: 91812 | I17: 8.6512422
A18: 13 | B18: 33.04.13 | C18: KARANGKOBAR | D18: 17008 | E18: 1.6026263 | F18: 15909 | G18: 1.49907 | H18: 32917 | I18: 3.1016963
A19: 14 | B19: 33.04.14 | C19: PAGENTAN | D19: 20488 | E19: 1.930539 | F19: 19526 | G19: 1.8398919 | H19: 40014 | I19: 3.7704309
A20: 15 | B20: 33.04.15 | C20: PEJAWARAN | D20: 23990 | E20: 2.2605248 | F20: 22324 | G20: 2.1035413 | H20: 46314 | I20: 4.364066
A21: 16 | B21: 33.04.16 | C21: BATUR | D21: 21980 | E21: 2.0711269 | F21: 20702 | G21: 1.9507038 | H21: 42682 | I21: 4.0218307
A22: 17 | B22: 33.04.17 | C22: WANAYASA | D22: 26773 | E22: 2.5227607 | F22: 25098 | G22: 2.3649292 | H22: 51871 | I22: 4.8876899
A23: 18 | B23: 33.04.18 | C23: KALIBENING | D23: 24796 | E23: 2.3364724 | F23: 23742 | G23: 2.2371563 | H23: 48538 | I23: 4.5736287
A24: 19 | B24: 33.04.19 | C24: PANDANARUM | D24: 12133 | E24: 1.1432658 | F24: 11558 | G24: 1.0890848 | H24: 23691 | I24: 2.2323507
A25: 20 | B25: 33.04.20 | C25: PAGEDONGAN | D25: 22758 | E25: 2.1444361 | F25: 21629 | G25: 2.038053 | H25: 44387 | I25: 4.1824891
A26: Jumlah Total | D26: =SUM(D6:D25) -> 539745 | E26: =D26/$H$26*100 -> 50.858981 | F26: =SUM(F6:F25) -> 521513 | G26: =F26/$H$26*100 -> 49.141019 | H26: =SUM(H6:H25) -> 1061258 | I26: =(D26+F26)/H26*100 -> 100

Sheet Desa
A1: Agregat Penduduk per Desa/Kelurahan
A3: Kecamatan : 33.04.01 SUSUKAN
A4: No | B4: Desa/Kelurahan | D4: Pria | F4: Wanita | H4: Jumlah
B5: Kode | C5: Nama | D5: Jumlah | E5: % | F5: Jumlah | G5: % | H5: Desa/Kel. | I5: %
A6: 1 | B6: {=RIGHT(_xlfn._xlws.FILTER('AGR_JK_3304_KAB. BANJARNEGARA'!$B$3:$B$300,(LEN('AGR_JK_3304_KAB. BANJARNEGARA'!$B$3:$B$300)=13)*(LEFT('AGR_JK_3304_KAB. BANJARNEGARA'!$B$3:$B$300,8)=MID(A3,13,8))),4)} -> 2001 | C6: {=_xlfn._xlws.FILTER('AGR_JK_3304_KAB. BANJARNEGARA'!$C$3:$D$300,(LEN('AGR_JK_3304_KAB. BANJARNEGARA'!$B$3:$B$300)=13)*(LEFT('AGR_JK_3304_KAB. BANJARNEGARA'!$B$3:$B$300,8)=MID(A3,13,8)))} -> BERTA | D6: 2055 | E6: {=D6:D20/$H$21*100} -> 3.1466765 | F6: {=_xlfn._xlws.FILTER('AGR_JK_3304_KAB. BANJARNEGARA'!$E$3:$E$300,(LEN('AGR_JK_3304_KAB. BANJARNEGARA'!$B$3:$B$300)=13)*(LEFT('AGR_JK_3304_KAB. BANJARNEGARA'!$B$3:$B$300,8)=MID(A3,13,8)))} -> 1961 | G6: {=F6:F20/$H$21*100} -> 3.0027409 | H6: {=_xlfn._xlws.FILTER('AGR_JK_3304_KAB. BANJARNEGARA'!$F$3:$F$300,(LEN('AGR_JK_3304_KAB. BANJARNEGARA'!$B$3:$B$300)=13)*(LEFT('AGR_JK_3304_KAB. BANJARNEGARA'!$B$3:$B$300,8)=MID(A3,13,8)))} -> 4016 | I6: {=H6:H20/$H$21*100} -> 6.1494174
A7: 2 | B7: 2002 | C7: DERIK | D7: 2140 | E7: 3.276831 | F7: 2124 | G7: 3.2523313 | H7: 4264 | I7: 6.5291623
A8: 3 | B8: 2003 | C8: GUMELEM WETAN | D8: 5459 | E8: 8.3589814 | F8: 5274 | G8: 8.075704 | H8: 10733 | I8: 16.434685
A9: 4 | B9: 2004 | C9: GUMELEM KULON | D9: 5478 | E9: 8.3880748 | F9: 5358 | G9: 8.2043273 | H9: 10836 | I9: 16.592402
A10: 5 | B10: 2005 | C10: PENARUSAN WETAN | D10: 1489 | E10: 2.2800006 | F10: 1455 | G10: 2.2279388 | H10: 2944 | I10: 4.5079394
A11: 6 | B11: 2006 | C11: PENARUSAN KULON | D11: 1330 | E11: 2.0365351 | F11: 1344 | G11: 2.0579723 | H11: 2674 | I11: 4.0945075
A12: 7 | B12: 2007 | C12: BRENGKOK | D12: 1479 | E12: 2.2646883 | F12: 1409 | G12: 2.1575023 | H12: 2888 | I12: 4.4221906
A13: 8 | B13: 2008 | C13: PEKIKIRAN | D13: 1459 | E13: 2.2340637 | F13: 1398 | G13: 2.1406587 | H13: 2857 | I13: 4.3747225
A14: 9 | B14: 2009 | C14: PIASA WETAN | D14: 650 | E14: 0.99529913 | F14: 672 | G14: 1.0289862 | H14: 1322 | I14: 2.0242853
A15: 10 | B15: 2010 | C15: KARANGSALAM | D15: 1400 | E15: 2.1437212 | F15: 1471 | G15: 2.2524385 | H15: 2871 | I15: 4.3961597
A16: 11 | B16: 2011 | C16: KEMRANGGON | D16: 1780 | E16: 2.7255884 | F16: 1785 | G16: 2.7332445 | H16: 3565 | I16: 5.4588329
A17: 12 | B17: 2012 | C17: SUSUKAN | D17: 2061 | E17: 3.1558638 | F17: 1957 | G17: 2.996616 | H17: 4018 | I17: 6.1524798
A18: 13 | B18: 2013 | C18: DERMASARI | D18: 1497 | E18: 2.2922504 | F18: 1514 | G18: 2.3182813 | H18: 3011 | I18: 4.6105318
... A20: 15 | B20: 2015 | C20: KARANGJATI | D20: 2440 | E20: 3.7361998 | F20: 2434 | G20: 3.7270124 | H20: 4874 | I20: 7.4632122
A21: Jumlah | D21: =SUM(D6:D20) -> 32943 | E21: =D21/$H$21*100 -> 50.443291 | F21: =SUM(F6:F20) -> 32364 | G21: =F21/$H$21*100 -> 49.556709 | H21: =SUM(H6:H20) -> 65307 | I21: =H21/$H$21*100 -> 100
A22: Kecamatan : 33.04.02 PURWAREJA KLAMPOK
A23: No | B23: Desa/Kelurahan | D23: Pria | F23: Wanita | H23: Jumlah
B24: Kode | C24: Nama | D24: Jumlah | E24: % | F24: Jumlah | G24: % | H24: Desa/Kel. | I24: %
A25: 16 | B25: {=RIGHT(_xlfn._xlws.FILTER('AGR_JK_3304_KAB. BANJARNEGARA'!$B$3:$B$300,(LEN('AGR_JK_3304_KAB. BANJARNEGARA'!$B$3:$B$300)=13)*(LEFT('AGR_JK_3304_KAB. BANJARNEGARA'!$B$3:$B$300,8)=MID(A22,13,8))),4)} -> 2001 | C25: {=_xlfn._xlws.FILTER('AGR_JK_3304_KAB. BANJARNEGARA'!$C$3:$D$300,(LEN('AGR_JK_3304_KAB. BANJARNEGARA'!$B$3:$B$300)=13)*(LEFT('AGR_JK_3304_KAB. BANJARNEGARA'!$B$3:$B$300,8)=MID(A22,13,8)))} -> SIRKANDI | D25: 3888 | E25: {=D25:D32/$H$33*100} -> 7.9249898 | F25: {=_xlfn._xlws.FILTER('AGR_JK_3304_KAB. BANJARNEGARA'!$E$3:$E$300,(LEN('AGR_JK_3304_KAB. BANJARNEGARA'!$B$3:$B$300)=13)*(LEFT('AGR_JK_3304_KAB. BANJARNEGARA'!$B$3:$B$300,8)=MID(A22,13,8)))} -> 3871 | G25: {=F25:F32/$H$33*100} -> 7.8903384 | H25: {=_xlfn._xlws.FILTER('AGR_JK_3304_KAB. BANJARNEGARA'!$F$3:$F$300,(LEN('AGR_JK_3304_KAB. BANJARNEGARA'!$B$3:$B$300)=13)*(LEFT('AGR_JK_3304_KAB. BANJARNEGARA'!$B$3:$B$300,8)=MID(A22,13,8)))} -> 7759 | I25: {=H25:H32/$H$33*100} -> 15.815328
A26: 17 | B26: 2002 | C26: PAGAK | D26: 1786 | E26: 3.6404403 | F26: 1787 | G26: 3.6424786 | H26: 3573 | I26: 7.2829189
A27: 18 | B27: 2003 | C27: KECITRAN | D27: 3129 | E27: 6.3779046 | F27: 3138 | G27: 6.3962495 | H27: 6267 | I27: 12.774154
A28: 19 | B28: 2004 | C28: PURWAREJA | D28: 4583 | E28: 9.3416225 | F28: 4485 | G28: 9.1418671 | H28: 9068 | I28: 18.48349
A29: 20 | B29: 2005 | C29: KLAMPOK | D29: 3587 | E29: 7.3114554 | F29: 3632 | G29: 7.4031798 | H29: 7219 | I29: 14.714635
A30: 21 | B30: 2006 | C30: KALILANDAK | D30: 1832 | E30: 3.734203 | F30: 1818 | G30: 3.7056665 | H30: 3650 | I30: 7.4398695
A31: 22 | B31: 2007 | C31: KALIMANDI | D31: 3264 | E31: 6.6530779 | F31: 3109 | G31: 6.3371382 | H31: 6373 | I31: 12.990216
A32: 23 | B32: 2008 | C32: KALIWINASUH | D32: 2572 | E32: 5.2425601 | F32: 2579 | G32: 5.2568284 | H32: 5151 | I32: 10.499389
A33: Jumlah | D33: =SUM(D25:D32) -> 24641 | E33: =D33/$H$33*100 -> 50.226254 | F33: =SUM(F25:F32) -> 24419 | G33: =F33/$H$33*100 -> 49.773746 | H33: =SUM(H25:H32) -> 49060 | I33: =H33/$H$33*100 -> 100
A34: Kecamatan : 33.04.03 MANDIRAJA
A35: No | B35: Desa/Kelurahan | D35: Pria | F35: Wanita | H35: Jumlah
B36: Kode | C36: Nama | D36: Jumlah | E36: % | F36: Jumlah | G36: % | H36: Desa/Kel. | I36: %
A37: 24 | B37: {=RIGHT(_xlfn._xlws.FILTER('AGR_JK_3304_KAB. BANJARNEGARA'!$B$3:$B$300,(LEN('AGR_JK_3304_KAB. BANJARNEGARA'!$B$3:$B$300)=13)*(LEFT('AGR_JK_3304_KAB. BANJARNEGARA'!$B$3:$B$300,8)=MID(A34,13,8))),4)} -> 2001 | C37: {=_xlfn._xlws.FILTER('AGR_JK_3304_KAB. BANJARNEGARA'!$C$3:$D$300,(LEN('AGR_JK_3304_KAB. BANJARNEGARA'!$B$3:$B$300)=13)*(LEFT('AGR_JK_3304_KAB. BANJARNEGARA'!$B$3:$B$300,8)=MID(A34,13,8)))} -> JALATUNDA | D37: 3003 | E37: {=D37:D52/$H$53*100} -> 3.6371344 | F37: {=_xlfn._xlws.FILTER('AGR_JK_3304_KAB. BANJARNEGARA'!$E$3:$E$300,(LEN('AGR_JK_3304_KAB. BANJARNEGARA'!$B$3:$B$300)=13)*(LEFT('AGR_JK_3304_KAB. BANJARNEGARA'!$B$3:$B$300,8)=MID(A34,13,8)))} -> 2912 | G37: {=F37:F52/$H$53*100} -> 3.5269182 | H37: {=_xlfn._xlws.FILTER('AGR_JK_3304_KAB. BANJARNEGARA'!$F$3:$F$300,(LEN('AGR_JK_3304_KAB. BANJARNEGARA'!$B$3:$B$300)=13)*(LEFT('AGR_JK_3304_KAB. BANJARNEGARA'!$B$3:$B$300,8)=MID(A34,13,8)))} -> 5915 | I37: {=H37:H52/$H$53*100} -> 7.1640526
A38: 25 | B38: 2002 | C38: SOMAWANGI | D38: 4814 | E38: 5.8305577 | F38: 4845 | G38: 5.8681039 | H38: 9659 | I38: 11.698662
A39: 26 | B39: 2003 | C39: KALIWUNGU | D39: 2378 | E39: 2.880155 | F39: 2362 | G39: 2.8607764 | H39: 4740 | I39: 5.7409314
A40: 27 | B40: 2004 | C40: KEBANARAN | D40: 3062 | E40: 3.7085932 | F40: 3037 | G40: 3.6783141 | H40: 6099 | I40: 7.3869073
A41: 28 | B41: 2005 | C41: GLEMPANG | D41: 3515 | E41: 4.2572519 | F41: 3448 | G41: 4.1761037 | H41: 6963 | I41: 8.4333555
A42: 29 | B42: 2006 | C42: SALAMERTA | D42: 2719 | E42: 3.293163 | F42: 2637 | G42: 3.1938473 | H42: 5356 | I42: 6.4870102
...
